<?xml version="1.0" ?>
<sdf version="1.7">
  <model name="panda">
    <pose>0 0 0 0 0 0</pose>
    <static>false</static>
    <self_collide>false</self_collide>
    <allow_auto_disable>true</allow_auto_disable>

    <!-- ros2_control inside Gazebo Sim (Fortress on Humble) -->
    <!-- If your system has libgz_ros2_control-system.so instead, swap filename below -->
    <plugin name="gz_ros2_control" filename="libign_ros2_control-system.so">
      <parameters>model://panda/config/ros2_control_panda.yaml</parameters>
    </plugin>

    <!-- Simplified inertias and shapes; replace with real values as needed -->

    <link name="panda_link0">
      <pose>0 0 0.0 0 0 0</pose>
      <inertial>
        <mass>5.0</mass>
        <inertia>
          <ixx>0.02</ixx><ixy>0</ixy><ixz>0</ixz>
          <iyy>0.02</iyy><iyz>0</iyz>
          <izz>0.02</izz>
        </inertia>
      </inertial>
      <visual name="base_vis">
        <geometry>
          <box><size>0.2 0.2 0.1</size></box>
        </geometry>
        <material><ambient>0.2 0.2 0.2 1</ambient></material>
      </visual>
      <collision name="base_col">
        <geometry>
          <box><size>0.2 0.2 0.1</size></box>
        </geometry>
      </collision>
    </link>

    <link name="panda_link1">
      <inertial><mass>2.0
        </mass><inertia><ixx>0.01</ixx><iyy>0.01</iyy><izz>0.01</izz><ixy>0</ixy><ixz>0</ixz><iyz>0</iyz></inertia></inertial>
      <visual name="l1_vis">
        <geometry><cylinder><radius>0.04</radius><length>0.3</length></cylinder></geometry>
      </visual>
      <collision name="l1_col">
        <geometry><cylinder><radius>0.04</radius><length>0.3</length></cylinder></geometry>
      </collision>
    </link>

    <link name="panda_link2">
      <inertial><mass>1.5
        </mass><inertia><ixx>0.008</ixx><iyy>0.008</iyy><izz>0.008</izz><ixy>0</ixy><ixz>0</ixz><iyz>0</iyz></inertia></inertial>
      <visual name="l2_vis">
        <geometry><cylinder><radius>0.035</radius><length>0.28</length></cylinder></geometry>
      </visual>
      <collision name="l2_col">
        <geometry><cylinder><radius>0.035</radius><length>0.28</length></cylinder></geometry>
      </collision>
    </link>

    <link name="panda_link3">
      <inertial><mass>1.3
        </mass><inertia><ixx>0.006</ixx><iyy>0.006</iyy><izz>0.006</izz><ixy>0</ixy><ixz>0</ixz><iyz>0</iyz></inertia></inertial>
      <visual name="l3_vis">
        <geometry><cylinder><radius>0.032</radius><length>0.25</length></cylinder></geometry>
      </visual>
      <collision name="l3_col">
        <geometry><cylinder><radius>0.032</radius><length>0.25</length></cylinder></geometry>
      </collision>
    </link>

    <link name="panda_link4">
      <inertial><mass>1.2
        </mass><inertia><ixx>0.005</ixx><iyy>0.005</iyy><izz>0.005</izz><ixy>0</ixy><ixz>0</ixz><iyz>0</iyz></inertia></inertial>
      <visual name="l4_vis">
        <geometry><cylinder><radius>0.03</radius><length>0.23</length></cylinder></geometry>
      </visual>
      <collision name="l4_col">
        <geometry><cylinder><radius>0.03</radius><length>0.23</length></cylinder></geometry>
      </collision>
    </link>

    <link name="panda_link5">
      <inertial><mass>1.1
        </mass><inertia><ixx>0.004</ixx><iyy>0.004</iyy><izz>0.004</izz><ixy>0</ixy><ixz>0</ixz><iyz>0</iyz></inertia></inertial>
      <visual name="l5_vis">
        <geometry><cylinder><radius>0.028</radius><length>0.20</length></cylinder></geometry>
      </visual>
      <collision name="l5_col">
        <geometry><cylinder><radius>0.028</radius><length>0.20</length></cylinder></geometry>
      </collision>
    </link>

    <link name="panda_link6">
      <inertial><mass>0.9
        </mass><inertia><ixx>0.003</ixx><iyy>0.003</iyy><izz>0.003</izz><ixy>0</ixy><ixz>0</ixz><iyz>0</iyz></inertia></inertial>
      <visual name="l6_vis">
        <geometry><cylinder><radius>0.026</radius><length>0.18</length></cylinder></geometry>
      </visual>
      <collision name="l6_col">
        <geometry><cylinder><radius>0.026</radius><length>0.18</length></cylinder></geometry>
      </collision>
    </link>

    <link name="panda_link7">
      <inertial><mass>0.8
        </mass><inertia><ixx>0.0025</ixx><iyy>0.0025</iyy><izz>0.0025</izz><ixy>0</ixy><ixz>0</ixz><iyz>0</iyz></inertia></inertial>
      <visual name="l7_vis">
        <geometry><cylinder><radius>0.024</radius><length>0.16</length></cylinder></geometry>
      </visual>
      <collision name="l7_col">
        <geometry><cylinder><radius>0.024</radius><length>0.16</length></cylinder></geometry>
      </collision>
    </link>

    <link name="panda_hand">
      <inertial><mass>0.6
        </mass><inertia><ixx>0.002</ixx><iyy>0.002</iyy><izz>0.002</izz><ixy>0</ixy><ixz>0</ixz><iyz>0</iyz></inertia></inertial>
      <visual name="hand_vis">
        <geometry><box><size>0.06 0.06 0.06</size></box></geometry>
      </visual>
      <collision name="hand_col">
        <geometry><box><size>0.06 0.06 0.06</size></box></geometry>
      </collision>
    </link>

    <!-- Single moving finger for simplicity (common for sim control) -->
    <link name="panda_finger_link1">
      <inertial><mass>0.2
        </mass><inertia><ixx>0.0005</ixx><iyy>0.0005</iyy><izz>0.0005</izz><ixy>0</ixy><ixz>0</ixz><iyz>0</iyz></inertia></inertial>
      <visual name="finger1_vis">
        <geometry><box><size>0.015 0.02 0.08</size></box></geometry>
      </visual>
      <collision name="finger1_col">
        <geometry><box><size>0.015 0.02 0.08</size></box></geometry>
      </collision>
    </link>

    <!-- Axes alternate Z/Y to roughly reflect a typical 7-DoF arm layout -->
    <joint name="panda_joint1" type="revolute">
      <parent>panda_link0</parent>
      <child>panda_link1</child>
      <pose>0 0 0.05 0 0 0</pose>
      <axis>
        <xyz>0 0 1</xyz>
        <limit><lower>-3.0</lower><upper>3.0</upper><effort>87</effort><velocity>2.0</velocity></limit>
        <dynamics><damping>0.2</damping></dynamics>
      </axis>
    </joint>

    <joint name="panda_joint2" type="revolute">
      <parent>panda_link1</parent>
      <child>panda_link2</child>
      <pose>0 0 0.15 0 0 0</pose>
      <axis>
        <xyz>0 1 0</xyz>
        <limit><lower>-3.0</lower><upper>3.0</upper><effort>87</effort><velocity>2.0</velocity></limit>
        <dynamics><damping>0.2</damping></dynamics>
      </axis>
    </joint>

    <joint name="panda_joint3" type="revolute">
      <parent>panda_link2</parent>
      <child>panda_link3</child>
      <pose>0 0 0.14 0 0 0</pose>
      <axis>
        <xyz>0 0 1</xyz>
        <limit><lower>-3.0</lower><upper>3.0</upper><effort>87</effort><velocity>2.0</velocity></limit>
        <dynamics><damping>0.2</damping></dynamics>
      </axis>
    </joint>

    <joint name="panda_joint4" type="revolute">
      <parent>panda_link3</parent>
      <child>panda_link4</child>
      <pose>0 0 0.125 0 0 0</pose>
      <axis>
        <xyz>0 1 0</xyz>
        <limit><lower>-3.0</lower><upper>3.0</upper><effort>87</effort><velocity>2.0</velocity></limit>
        <dynamics><damping>0.2</damping></dynamics>
      </axis>
    </joint>

    <joint name="panda_joint5" type="revolute">
      <parent>panda_link4</parent>
      <child>panda_link5</child>
      <pose>0 0 0.115 0 0 0</pose>
      <axis>
        <xyz>0 0 1</xyz>
        <limit><lower>-3.0</lower><upper>3.0</upper><effort>12</effort><velocity>2.0</velocity></limit>
        <dynamics><damping>0.15</damping></dynamics>
      </axis>
    </joint>

    <joint name="panda_joint6" type="revolute">
      <parent>panda_link5</parent>
      <child>panda_link6</child>
      <pose>0 0 0.10 0 0 0</pose>
      <axis>
        <xyz>0 1 0</xyz>
        <limit><lower>-3.0</lower><upper>3.0</upper><effort>12</effort><velocity>2.0</velocity></limit>
        <dynamics><damping>0.15</damping></dynamics>
      </axis>
    </joint>

    <joint name="panda_joint7" type="revolute">
      <parent>panda_link6</parent>
      <child>panda_link7</child>
      <pose>0 0 0.09 0 0 0</pose>
      <axis>
        <xyz>0 0 1</xyz>
        <limit><lower>-3.0</lower><upper>3.0</upper><effort>12</effort><velocity>2.0</velocity></limit>
        <dynamics><damping>0.1</damping></dynamics>
      </axis>
    </joint>

    <joint name="panda_hand_joint" type="fixed">
      <parent>panda_link7</parent>
      <child>panda_hand</child>
      <pose>0 0 0.08 0 0 0</pose>
    </joint>

    <!-- Single prismatic finger (simple gripper model). Many configs control only one joint. -->
    <joint name="panda_finger_joint1" type="prismatic">
      <parent>panda_hand</parent>
      <child>panda_finger_link1</child>
      <pose>0 0 0.03 0 0 0</pose>
      <axis>
        <xyz>0 1 0</xyz>
        <limit><lower>0.0</lower><upper>0.04</upper><effort>20</effort><velocity>0.2</velocity></limit>
        <dynamics><damping>0.05</damping></dynamics>
      </axis>
    </joint>

  </model>
</sdf>
<?xml version="1.0" ?>
<sdf version="1.7">
  <model name="panda">
    <pose>0 0 0 0 0 0</pose>
    <static>false</static>
    <self_collide>false</self_collide>
    <allow_auto_disable>true</allow_auto_disable>

    <!-- ros2_control inside Gazebo Sim (Fortress on Humble) -->
    <!-- If your system has libgz_ros2_control-system.so instead, swap filename below -->
    <plugin name="gz_ros2_control" filename="libign_ros2_control-system.so">
      <parameters>model://panda/config/ros2_control_panda.yaml</parameters>
    </plugin>

    <!-- Simplified inertias and shapes; replace with real values as needed -->

    <link name="panda_link0">
      <pose>0 0 0.0 0 0 0</pose>
      <inertial>
        <mass>5.0</mass>
        <inertia>
          <ixx>0.02</ixx><ixy>0</ixy><ixz>0</ixz>
          <iyy>0.02</iyy><iyz>0</iyz>
          <izz>0.02</izz>
        </inertia>
      </inertial>
      <visual name="base_vis">
        <geometry>
          <box><size>0.2 0.2 0.1</size></box>
        </geometry>
        <material><ambient>0.2 0.2 0.2 1</ambient></material>
      </visual>
      <collision name="base_col">
        <geometry>
          <box><size>0.2 0.2 0.1</size></box>
        </geometry>
      </collision>
    </link>

    <link name="panda_link1">
      <inertial><mass>2.0
        </mass><inertia><ixx>0.01</ixx><iyy>0.01</iyy><izz>0.01</izz><ixy>0</ixy><ixz>0</ixz><iyz>0</iyz></inertia></inertial>
      <visual name="l1_vis">
        <geometry><cylinder><radius>0.04</radius><length>0.3</length></cylinder></geometry>
      </visual>
      <collision name="l1_col">
        <geometry><cylinder><radius>0.04</radius><length>0.3</length></cylinder></geometry>
      </collision>
    </link>

    <link name="panda_link2">
      <inertial><mass>1.5
        </mass><inertia><ixx>0.008</ixx><iyy>0.008</iyy><izz>0.008</izz><ixy>0</ixy><ixz>0</ixz><iyz>0</iyz></inertia></inertial>
      <visual name="l2_vis">
        <geometry><cylinder><radius>0.035</radius><length>0.28</length></cylinder></geometry>
      </visual>
      <collision name="l2_col">
        <geometry><cylinder><radius>0.035</radius><length>0.28</length></cylinder></geometry>
      </collision>
    </link>

    <link name="panda_link3">
      <inertial><mass>1.3
        </mass><inertia><ixx>0.006</ixx><iyy>0.006</iyy><izz>0.006</izz><ixy>0</ixy><ixz>0</ixz><iyz>0</iyz></inertia></inertial>
      <visual name="l3_vis">
        <geometry><cylinder><radius>0.032</radius><length>0.25</length></cylinder></geometry>
      </visual>
      <collision name="l3_col">
        <geometry><cylinder><radius>0.032</radius><length>0.25</length></cylinder></geometry>
      </collision>
    </link>

    <link name="panda_link4">
      <inertial><mass>1.2
        </mass><inertia><ixx>0.005</ixx><iyy>0.005</iyy><izz>0.005</izz><ixy>0</ixy><ixz>0</ixz><iyz>0</iyz></inertia></inertial>
      <visual name="l4_vis">
        <geometry><cylinder><radius>0.03</radius><length>0.23</length></cylinder></geometry>
      </visual>
      <collision name="l4_col">
        <geometry><cylinder><radius>0.03</radius><length>0.23</length></cylinder></geometry>
      </collision>
    </link>

    <link name="panda_link5">
      <inertial><mass>1.1
        </mass><inertia><ixx>0.004</ixx><iyy>0.004</iyy><izz>0.004</izz><ixy>0</ixy><ixz>0</ixz><iyz>0</iyz></inertia></inertial>
      <visual name="l5_vis">
        <geometry><cylinder><radius>0.028</radius><length>0.20</length></cylinder></geometry>
      </visual>
      <collision name="l5_col">
        <geometry><cylinder><radius>0.028</radius><length>0.20</length></cylinder></geometry>
      </collision>
    </link>

    <link name="panda_link6">
      <inertial><mass>0.9
        </mass><inertia><ixx>0.003</ixx><iyy>0.003</iyy><izz>0.003</izz><ixy>0</ixy><ixz>0</ixz><iyz>0</iyz></inertia></inertial>
      <visual name="l6_vis">
        <geometry><cylinder><radius>0.026</radius><length>0.18</length></cylinder></geometry>
      </visual>
      <collision name="l6_col">
        <geometry><cylinder><radius>0.026</radius><length>0.18</length></cylinder></geometry>
      </collision>
    </link>

    <link name="panda_link7">
      <inertial><mass>0.8
        </mass><inertia><ixx>0.0025</ixx><iyy>0.0025</iyy><izz>0.0025</izz><ixy>0</ixy><ixz>0</ixz><iyz>0</iyz></inertia></inertial>
      <visual name="l7_vis">
        <geometry><cylinder><radius>0.024</radius><length>0.16</length></cylinder></geometry>
      </visual>
      <collision name="l7_col">
        <geometry><cylinder><radius>0.024</radius><length>0.16</length></cylinder></geometry>
      </collision>
    </link>

    <link name="panda_hand">
      <inertial><mass>0.6
        </mass><inertia><ixx>0.002</ixx><iyy>0.002</iyy><izz>0.002</izz><ixy>0</ixy><ixz>0</ixz><iyz>0</iyz></inertia></inertial>
      <visual name="hand_vis">
        <geometry><box><size>0.06 0.06 0.06</size></box></geometry>
      </visual>
      <collision name="hand_col">
        <geometry><box><size>0.06 0.06 0.06</size></box></geometry>
      </collision>
    </link>

    <!-- Single moving finger for simplicity (common for sim control) -->
    <link name="panda_finger_link1">
      <inertial><mass>0.2
        </mass><inertia><ixx>0.0005</ixx><iyy>0.0005</iyy><izz>0.0005</izz><ixy>0</ixy><ixz>0</ixz><iyz>0</iyz></inertia></inertial>
      <visual name="finger1_vis">
        <geometry><box><size>0.015 0.02 0.08</size></box></geometry>
      </visual>
      <collision name="finger1_col">
        <geometry><box><size>0.015 0.02 0.08</size></box></geometry>
      </collision>
    </link>

    <!-- Axes alternate Z/Y to roughly reflect a typical 7-DoF arm layout -->
    <joint name="panda_joint1" type="revolute">
      <parent>panda_link0</parent>
      <child>panda_link1</child>
      <pose>0 0 0.05 0 0 0</pose>
      <axis>
        <xyz>0 0 1</xyz>
        <limit><lower>-3.0</lower><upper>3.0</upper><effort>87</effort><velocity>2.0</velocity></limit>
        <dynamics><damping>0.2</damping></dynamics>
      </axis>
    </joint>

    <joint name="panda_joint2" type="revolute">
      <parent>panda_link1</parent>
      <child>panda_link2</child>
      <pose>0 0 0.15 0 0 0</pose>
      <axis>
        <xyz>0 1 0</xyz>
        <limit><lower>-3.0</lower><upper>3.0</upper><effort>87</effort><velocity>2.0</velocity></limit>
        <dynamics><damping>0.2</damping></dynamics>
      </axis>
    </joint>

    <joint name="panda_joint3" type="revolute">
      <parent>panda_link2</parent>
      <child>panda_link3</child>
      <pose>0 0 0.14 0 0 0</pose>
      <axis>
        <xyz>0 0 1</xyz>
        <limit><lower>-3.0</lower><upper>3.0</upper><effort>87</effort><velocity>2.0</velocity></limit>
        <dynamics><damping>0.2</damping></dynamics>
      </axis>
    </joint>

    <joint name="panda_joint4" type="revolute">
      <parent>panda_link3</parent>
      <child>panda_link4</child>
      <pose>0 0 0.125 0 0 0</pose>
      <axis>
        <xyz>0 1 0</xyz>
        <limit><lower>-3.0</lower><upper>3.0</upper><effort>87</effort><velocity>2.0</velocity></limit>
        <dynamics><damping>0.2</damping></dynamics>
      </axis>
    </joint>

    <joint name="panda_joint5" type="revolute">
      <parent>panda_link4</parent>
      <child>panda_link5</child>
      <pose>0 0 0.115 0 0 0</pose>
      <axis>
        <xyz>0 0 1</xyz>
        <limit><lower>-3.0</lower><upper>3.0</upper><effort>12</effort><velocity>2.0</velocity></limit>
        <dynamics><damping>0.15</damping></dynamics>
      </axis>
    </joint>

    <joint name="panda_joint6" type="revolute">
      <parent>panda_link5</parent>
      <child>panda_link6</child>
      <pose>0 0 0.10 0 0 0</pose>
      <axis>
        <xyz>0 1 0</xyz>
        <limit><lower>-3.0</lower><upper>3.0</upper><effort>12</effort><velocity>2.0</velocity></limit>
        <dynamics><damping>0.15</damping></dynamics>
      </axis>
    </joint>

    <joint name="panda_joint7" type="revolute">
      <parent>panda_link6</parent>
      <child>panda_link7</child>
      <pose>0 0 0.09 0 0 0</pose>
      <axis>
        <xyz>0 0 1</xyz>
        <limit><lower>-3.0</lower><upper>3.0</upper><effort>12</effort><velocity>2.0</velocity></limit>
        <dynamics><damping>0.1</damping></dynamics>
      </axis>
    </joint>

    <joint name="panda_hand_joint" type="fixed">
      <parent>panda_link7</parent>
      <child>panda_hand</child>
      <pose>0 0 0.08 0 0 0</pose>
    </joint>

    <!-- Single prismatic finger (simple gripper model). Many configs control only one joint. -->
    <joint name="panda_finger_joint1" type="prismatic">
      <parent>panda_hand</parent>
      <child>panda_finger_link1</child>
      <pose>0 0 0.03 0 0 0</pose>
      <axis>
        <xyz>0 1 0</xyz>
        <limit><lower>0.0</lower><upper>0.04</upper><effort>20</effort><velocity>0.2</velocity></limit>
        <dynamics><damping>0.05</damping></dynamics>
      </axis>
    </joint>

  </model>
</sdf>
